<!--
Copyright (c) 2020, NVIDIA CORPORATION. All rights reserved.

NVIDIA CORPORATION and its licensors retain all intellectual property
and proprietary rights in and to this software, related documentation
and any modifications thereto. Any use, reproduction, disclosure or
distribution of this software and related documentation without an express
license agreement from NVIDIA CORPORATION is strictly prohibited.
-->

<robot name="UR10_CB3">
    <link name="base">
        <visual>
            <origin xyz="0 0 0.005" rpy="0 0 0"/>
            <geometry>
                <cylinder radius="0.075" length="0.01"/>
            </geometry>
        </visual>
        <inertial>
            <mass value="7.1"/>
            <inertia ixx="1.0" ixy="0.0" ixz="0.0" iyy="1.0" iyz="0.0" izz="1.0"/>
        </inertial>
    </link>
    <link name="shoulder" >
        <visual>
            <origin xyz="0 0.0 0.1125" rpy="0 0 0"/>
            <geometry>
                <cylinder radius="0.075" length="0.20"/>
            </geometry>
        </visual>
        <visual>
            <origin xyz="0 .05 0.128" rpy="1.57079632679 0 0"/>
            <geometry>
                <cylinder radius="0.075" length="0.1"/>
            </geometry>
        </visual>
        <inertial>
            <mass value="12.7"/>
            <inertia ixx="1.0" ixy="0.0" ixz="0.0" iyy="1.0" iyz="0.0" izz="1.0"/>
        </inertial>
    </link>
    <link name="elbow" >
        <visual>
            <origin xyz="0 0 0" rpy="1.57079632679 0 0"/>
            <geometry>
                <cylinder radius="0.075" length="0.15"/>
            </geometry>
        </visual>
        <visual>
            <origin xyz="0.306 0 0" rpy="1.57079632679 1.57079632679 0"/>
            <geometry>
                <cylinder radius="0.06" length="0.612"/>
            </geometry>
        </visual>
        <visual>
            <origin xyz="0.612 0 0" rpy="1.57079632679 0 0"/>
            <geometry>
                <cylinder radius="0.06" length="0.12"/>
            </geometry>
        </visual>
        <inertial>
            <mass value="4.27"/>
            <inertia ixx="1.0" ixy="0.0" ixz="0.0" iyy="1.0" iyz="0.0" izz="1.0"/>
        </inertial>
    </link>
    <link name="wrist_1" >
        <visual>
            <origin xyz="0 0 0" rpy="1.57079632679 0 0"/>
            <geometry>
                <cylinder radius="0.06" length="0.12"/>
            </geometry>
        </visual>
        <visual>
            <origin xyz="0.286 0 0" rpy="1.57079632679 1.57079632679 0"/>
            <geometry>
                <cylinder radius="0.05" length="0.572"/>
            </geometry>
        </visual>
        <visual>
            <origin xyz="0.572 0 0" rpy="1.57079632679 0 0"/>
            <geometry>
                <cylinder radius="0.05" length="0.1"/>
            </geometry>
        </visual>
        <inertial>
            <mass value="2"/>
            <inertia ixx="1.0" ixy="0.0" ixz="0.0" iyy="1.0" iyz="0.0" izz="1.0"/>
        </inertial>
    </link>
    <link name="wrist_2" >
        <visual>
            <origin xyz="0.0 -0.005 0" rpy="1.57079632679 0 0"/>
            <geometry>
                <cylinder radius="0.05" length="0.110"/>
            </geometry>
        </visual>
        <visual>
            <origin xyz="0.0 0 -0.03" rpy="0 0 0"/>
            <geometry>
                <cylinder radius="0.05" length="0.06"/>
            </geometry>
        </visual>
        <inertial>
            <mass value="2"/>
            <inertia ixx="1.0" ixy="0.0" ixz="0.0" iyy="1.0" iyz="0.0" izz="1.0"/>
        </inertial>
    </link>
    <link name="wrist_3" >
        <visual>
            <origin xyz="0.0 0 0.0" rpy="0 0 0"/>
            <geometry>
                <cylinder radius="0.05" length="0.10"/>
            </geometry>
        </visual>
        <visual>
            <origin xyz="0.0 0.035 0.0" rpy="1.57079632679 0 0"/>
            <geometry>
                <cylinder radius="0.05" length="0.07"/>
            </geometry>
        </visual>
        <inertial>
            <mass value="0.365"/>
            <inertia ixx="1.0" ixy="0.0" ixz="0.0" iyy="1.0" iyz="0.0" izz="1.0"/>
        </inertial>
    </link>
    <link name="tool" >
        <inertial>
            <mass value="0.01"/>
            <inertia ixx="1.0" ixy="0.0" ixz="0.0" iyy="1.0" iyz="0.0" izz="1.0"/>
        </inertial>
        <visual>
            <origin xyz="-0.01 0 0.0" rpy="0 1.57079632679 0"/>
            <geometry>
                <cylinder radius="0.05" length="0.02"/>
            </geometry>
        </visual>
    </link>
    <joint name="shoulder_pan_joint" type="revolute">
        <origin xyz="0 0 0" rpy="0 0 0"/>
        <axis xyz="0 0 1" />
        <limit upper="6.28318" lower="-6.28318" velocity="2.0944" effort="330" />
        <parent link="base" />
        <child link ="shoulder" />
    </joint>
    <joint name="shoulder_lift_joint" type="revolute">
        <origin xyz="0 .176 0.128" rpy="0 0 0"/>
        <axis xyz="0 1 0" />
        <limit upper="6.28318" lower="-6.28318" velocity="2.0944" effort="330.0" />
        <parent link ="shoulder" />
        <child link="elbow" />
    </joint>
    <joint name="elbow_joint" type="revolute">
        <origin xyz="0.612 -0.128 0" rpy="0 0 0"/>
        <axis xyz="0 1 0" />
        <limit upper="6.28318" lower="-6.28318" velocity="3.14159" effort="150.0" />
        <parent link ="elbow" />
        <child link="wrist_1" />
    </joint>
    <joint name="wrist_1_joint" type="revolute">
        <origin xyz="0.572 0.116 0" rpy="0 0 0"/>
        <axis xyz="0 1 0" />
        <limit upper="6.28318" lower="-6.28318" velocity="3.14159" effort="56.0" />
        <parent link ="wrist_1" />
        <child link="wrist_2" />
    </joint>
    <joint name="wrist_2_joint" type="revolute">
        <origin xyz="0 0 -0.116" rpy="0 0 0"/>
        <axis xyz="0 0 -1" />
        <limit upper="6.28318" lower="-6.28318" velocity="3.14159" effort="56.0" />
        <parent link ="wrist_2" />
        <child link="wrist_3" />
    </joint>
    <joint name="wrist_3_joint" type="revolute">
        <origin xyz="0 0.092 0" rpy="0 0 1.57079632679"/>
        <axis xyz="1 0 0" />
        <limit upper="6.28318" lower="-6.28318" velocity="3.14159" effort="56.0" />
        <parent link ="wrist_3" />
        <child link="tool" />
    </joint>

<link name="world"/>
    <joint name="world_joint" type="fixed">
        <parent link="world"/>
        <child link="base"/>
        <origin rpy="0.0 0.0 0.0" xyz="0.0 0.0 0.0"/>
    </joint>
</robot>
